Workbook

Sheet янв
A1: месяц | B1: ед.изм | C1: Кравец Е.А. (САО) | D1: Лощинина М.А. (САО) | E1: Павлова Ю.В. (КАО) | F1: Кель М.В. (КАО) | G1: Епанчинцева Ю.Н. (ЦАО) | H1: Колонтаева А.Н. (ОАО) | I1: Барныч Г.М. (ОАО) | J1: Колонтаева А.Н. (ЛАО) | K1: Барныч Г.М. (ЛАО) | L1: Итого
A2: Принято участие в с/з, беседах | B2: к-во | C2: 26 | D2: 20 | E2: 13 | F2: 0 | G2: 39 | H2: 16 | I2: 0 | J2: 2 | K2: 0 | L2: =SUM(C2:K2)
A3: Предъявлено заявлений о вынесении судебного приказа | B3: к-во | C3: 0 | D3: 56 | E3: 0 | F3: 0 | G3: 0 | H3: 109 | I3: 17 | J3: 29 | K3: 13 | L3: =SUM(C3:K3)
B4: долг | C4: 0 | D4: 3307299.4 | E4: 0 | F4: 0 | G4: 0 | H4: 4978328.7 | I4: 1276914.6 | J4: 2179254.4 | K4: 694116.38 | L4: =SUM(C4:K4)
B5: пени | C5: 0 | D5: 2014260.3 | E5: 0 | F5: 0 | G5: 0 | H5: 2392019.5 | I5: 1027867.9 | J5: 1700102.6 | K5: 997931.3 | L5: =SUM(C5:K5)
B6: г/п | C6: 0 | D6: 112000 | E6: 0 | F6: 0 | G6: 0 | H6: 220699 | I6: 45406 | J6: 73640 | K6: 37409 | L6: =SUM(C6:K6)
A7: Удовлетворено в пользу АО "Омск РТС" заявлений о вынесении судебных приказов | B7: к-во | C7: 0 | D7: 44 | E7: 0 | F7: 0 | G7: 0 | H7: 100 | I7: 0 | J7: 0 | K7: 0 | L7: =SUM(C7:K7)
B8: долг | C8: 0 | D8: 2875139.1 | E8: 0 | F8: 0 | G8: 0 | H8: 5701679 | I8: 0 | J8: 0 | K8: 0 | L8: =SUM(C8:K8)
B9: пени | C9: 0 | D9: 2348987 | E9: 0 | F9: 0 | G9: 0 | H9: 2091678 | I9: 0 | J9: 0 | K9: 0 | L9: =SUM(C9:K9)
B10: г/п | C10: 0 | D10: 92357 | E10: 0 | F10: 0 | G10: 0 | H10: 101098 | I10: 0 | J10: 0 | K10: 0 | L10: =SUM(C10:K10)
A11: Заявления нах-ся в стадии рассмотрения | B11: к-во | C11: 48 | D11: 0 | E11: 1237 | F11: 1122 | G11: 1026 | H11: 156 | I11: 17 | J11: 103 | K11: 13 | L11: =SUM(C11:K11)
B12: долг | C12: 4574321.1 | D12: 0 | E12: 50519904 | F12: 50132433 | G12: 62379092 | H12: 6205103.5 | I12: 1276914.6 | J12: 8074440.3 | K12: 694116.38 | L12: =SUM(C12:K12)
B13: пени | C13: 4003002.2 | D13: 0 | E13: 32835595 | F13: 54806916 | G13: 49793436 | H13: 5343103.2 | I13: 1027867.9 | J13: 9017322.2 | K13: 997931.3 | L13: =SUM(C13:K13)
B14: г/п | C14: 243826 | D14: 0 | E14: 3911723.7 | F14: 60280408 | G14: 1844901.3 | H14: 197886 | I14: 45406 | J14: 336400 | K14: 37409 | L14: =SUM(C14:K14)
A15: Получено исполнительных документов | B15: к-во | C15: 0 | D15: 0 | E15: 0 | F15: 0 | G15: 0 | H15: 88 | I15: 0 | J15: 0 | K15: 0 | L15: =SUM(C15:K15)
B16: долг | C16: 0 | D16: 0 | E16: 0 | F16: 0 | G16: 0 | H16: 2252245.3 | I16: 0 | J16: 0 | K16: 0 | L16: =SUM(C16:K16)
B17: пени | C17: 0 | D17: 0 | E17: 0 | F17: 0 | G17: 0 | H17: 1769469.6 | I17: 0 | J17: 0 | K17: 0 | L17: =SUM(C17:K17)
B18: г/п | C18: 0 | D18: 0 | E18: 0 | F18: 0 | G18: 0 | H18: 140931.59 | I18: 0 | J18: 0 | K18: 0 | L18: =SUM(C18:K18)
A19: Отказ от иска в связи с оплатой долга | B19: к-во | C19: 0 | D19: 0 | E19: 0 | F19: 0 | G19: 0 | H19: 0 | I19: 0 | J19: 0 | K19: 0 | L19: =SUM(C19:K19)
B20: долг | C20: 0 | D20: 0 | E20: 0 | F20: 0 | G20: 0 | H20: 0 | I20: 0 | J20: 0 | K20: 0 | L20: 0
B21: пени | C21: 0 | D21: 0 | E21: 0 | F21: 0 | G21: 0 | H21: 0 | I21: 0 | J21: 0 | K21: 0 | L21: 0
A22: Направлено исполнительных документов в УФССП, ПФ РФ, Сбербанк РФ | B22: к-во/р.с | C22: 0 | D22: 0 | E22: 0 | F22: 0 | G22: 0 | H22: 88/55 | I22: 0 | J22: 0 | K22: 0 | L22: 88/55
B23: долг | C23: 0 | D23: 0 | E23: 0 | F23: 0 | G23: 0 | H23: 2252245.3 | I23: 0 | J23: 0 | K23: 0 | L23: =SUM(C23:K23)
B24: пени | C24: 0 | D24: 0 | E24: 0 | F24: 0 | G24: 0 | H24: 1769469.6 | I24: 0 | J24: 0 | K24: 0 | L24: =SUM(C24:K24)
B25: г/п | C25: 0 | D25: 0 | E25: 0 | F25: 0 | G25: 0 | H25: 140931.59 | I25: 0 | J25: 0 | K25: 0 | L25: =SUM(C25:K25)
A26: Оплачено г/п (по физ.лицам) | B26: сумма | C26: 0 | D26: 0 | E26: 0 | F26: 0 | G26: 0 | H26: 20000 | I26: 0 | J26: 320178 | K26: 0 | L26: =SUM(C26:K26)
A27: Применен судом срок исковой давности | B27: к-во | C27: 62 | D27: 0 | E27: 0 | F27: 0 | G27: 0 | H27: 0 | I27: 0 | J27: 0 | K27: 0 | L27: =SUM(C27:K27)
B28: сумма | C28: 1445538.2 | D28: 0 | E28: 0 | F28: 0 | G28: 0 | H28: 0 | I28: 0 | J28: 0 | K28: 0 | L28: =SUM(C28:K28)
A29: Возвращено ден. ср. через ССП (сумма) | B29: долг | C29: 736953.34 | D29: 0 | E29: 191852.94 | F29: 0 | G29: 773517.42 | H29: 613200.89 | I29: 0 | J29: 39208.99 | K29: 0 | L29: =SUM(C29:K29)
B30: пени | C30: 261072.99 | D30: 0 | E30: 190254.62 | F30: 0 | G30: 165911.58 | H30: 139585.69 | I30: 0 | J30: 206.22 | K30: 0 | L30: =SUM(C30:K30)
A31: Возвращено ден. ср. через Сбербанк и Пенсионный (сумма) | B31: долг | C31: 1059851.1 | D31: 0 | E31: 928002.47 | F31: 0 | G31: 1043977.3 | H31: 1011164 | I31: 0 | J31: 16518.38 | K31: 0 | L31: =SUM(C31:K31)
A32: Предъявлено исковых заявлений | B32: к-во | C32: 12 | D32: 0 | E32: 0 | F32: 0 | G32: 0 | H32: 0 | I32: 0 | J32: 1 | K32: 0 | L32: =SUM(C32:K32)
B33: долг | C33: 534255.4 | D33: 0 | E33: 0 | F33: 0 | G33: 0 | H33: 0 | I33: 0 | J33: 87533.03 | K33: 0 | L33: =SUM(C33:K33)
B34: пени | C34: 748211.25 | D34: 0 | E34: 0 | F34: 0 | G34: 0 | H34: 0 | I34: 0 | J34: 19866.63 | K34: 0 | L34: =SUM(C34:K34)
B35: г/п | C35: 28000 | D35: 0 | E35: 0 | F35: 0 | G35: 0 | H35: 0 | I35: 0 | J35: 4222 | K35: 0 | L35: =SUM(C35:K35)
A36: Удовлетворено в пользу АО "Омск РТС" исковых заявлений | B36: к-во | C36: 0 | D36: 0 | E36: 0 | F36: 0 | G36: 0 | H36: 8 | I36: 0 | J36: 0 | K36: 0 | L36: =SUM(C36:K36)
B37: долг | C37: 0 | D37: 0 | E37: 0 | F37: 0 | G37: 0 | H37: 480703.7 | I37: 0 | J37: 0 | K37: 0 | L37: =SUM(C37:K37)
B38: пени | C38: 0 | D38: 0 | E38: 0 | F38: 0 | G38: 0 | H38: 344397.02 | I38: 0 | J38: 0 | K38: 0 | L38: =SUM(C38:K38)
B39: г/п | C39: 0 | D39: 0 | E39: 0 | F39: 0 | G39: 0 | H39: 40714 | I39: 0 | J39: 0 | K39: 0 | L39: =SUM(C39:K39)
A40: Подготовка правового заключения о списании ДЗ | B40: к-во | C40: 2 | D40: 0 | E40: 2 | F40: 0 | G40: 0 | H40: 1 | I40: 0 | J40: 0 | K40: 0 | L40: =SUM(C40:K40)
...

Sheet фев
A1: месяц | B1: ед.изм | C1: Кравец Е.А. (САО) | D1: Лощинина М.А. (САО) | E1: Павлова Ю.В. (КАО) | F1: Кель М.В. (КАО) | G1: Епанчинцева Ю.Н. (ЦАО) | H1: Колонтаева А.Н. (ОАО) | I1: Барныч Г.М. (ОАО) | J1: Колонтаева А.Н. (ЛАО) | K1: Барныч Г.М. (ЛАО) | L1: Итого
A2: Принято участие в с/з, беседах | B2: к-во | C2: 8 | D2: 15 | E2: 26 | F2: 2 | G2: 42 | H2: 39 | I2: 0 | J2: 2 | K2: 0 | L2: =SUM(C2:K2)
A3: Предъявлено заявлений о вынесении судебного приказа | B3: к-во | C3: 0 | D3: 71 | E3: 0 | F3: 72 | G3: 0 | H3: 0 | I3: 150 | J3: 0 | K3: 50 | L3: =SUM(C3:K3)
B4: долг | C4: 0 | D4: 7996754.5 | E4: 0 | F4: 4674483.1 | G4: 0 | H4: 0 | I4: 8142383.3 | J4: 0 | K4: 3271442.1 | L4: =SUM(C4:K4)
B5: пени | C5: 0 | D5: 3821651.4 | E5: 0 | F5: 4247249.8 | G5: 0 | H5: 0 | I5: 4866486.5 | J5: 0 | K5: 2430417 | L5: =SUM(C5:K5)
B6: г/п | C6: 0 | D6: 173651 | E6: 0 | F6: 189459 | G6: 0 | H6: 0 | I6: 322879 | J6: 0 | K6: 77514 | L6: =SUM(C6:K6)
A7: Удовлетворено в пользу АО "Омск РТС" заявлений о вынесении судебных приказов | B7: к-во | C7: 0 | D7: 0 | E7: 0 | F7: 0 | G7: 30 | H7: 0 | I7: 0 | J7: 0 | K7: 0 | L7: =SUM(C7:K7)
B8: долг | C8: 0 | D8: 0 | E8: 0 | F8: 0 | G8: 1326969.2 | H8: 0 | I8: 0 | J8: 0 | K8: 0 | L8: =SUM(C8:K8)
B9: пени | C9: 0 | D9: 0 | E9: 0 | F9: 0 | G9: 745987.22 | H9: 0 | I9: 0 | J9: 0 | K9: 0 | L9: =SUM(C9:K9)
B10: г/п | C10: 0 | D10: 0 | E10: 0 | F10: 0 | G10: 74782.79 | H10: 0 | I10: 0 | J10: 0 | K10: 0 | L10: =SUM(C10:K10)
A11: Заявления нах-ся в стадии рассмотрения | B11: к-во | C11: 159 | D11: 0 | E11: 1287 | F11: 1194 | G11: 993 | H11: 196 | I11: 167 | J11: 102 | K11: 50 | L11: =SUM(C11:K11)
B12: долг | C12: 10921474 | D12: 0 | E12: 50519904 | F12: 54806916 | G12: 59744666 | H12: 8188094.9 | I12: 9419297.9 | J12: 8070305.6 | K12: 3271442.1 | L12: =SUM(C12:K12)
B13: пени | C13: 8647325.1 | D13: 0 | E13: 32835595 | F13: 32036746 | G13: 48487934 | H13: 7436732.4 | I13: 5894354.5 | J13: 9011470.5 | K13: 2430417 | L13: =SUM(C13:K13)
B14: г/п | C14: 507502 | D14: 0 | E14: 3911723.7 | F14: 2233417.5 | G14: 1534121.2 | H14: 381219 | I14: 368285 | J14: 332400 | K14: 77514 | L14: =SUM(C14:K14)
A15: Получено исполнительных документов | B15: к-во | C15: 0 | D15: 0 | E15: 0 | F15: 0 | G15: 55 | H15: 11 | I15: 0 | J15: 0 | K15: 0 | L15: =SUM(C15:K15)
B16: долг | C16: 0 | D16: 0 | E16: 0 | F16: 0 | G16: 1326969.2 | H16: 201671.02 | I16: 0 | J16: 0 | K16: 0 | L16: =SUM(C16:K16)
B17: пени | C17: 0 | D17: 0 | E17: 0 | F17: 0 | G17: 745987.22 | H17: 59011 | I17: 0 | J17: 0 | K17: 0 | L17: =SUM(C17:K17)
B18: г/п | C18: 0 | D18: 0 | E18: 0 | F18: 0 | G18: 74782.79 | H18: 22000 | I18: 0 | J18: 0 | K18: 0 | L18: =SUM(C18:K18)
A19: Отказ от иска в связи с оплатой долга | B19: к-во | C19: 0 | D19: 0 | E19: 0 | F19: 0 | G19: 0 | H19: 1 | I19: 0 | J19: 0 | K19: 0 | L19: =SUM(C19:K19)
B20: долг | C20: 0 | D20: 0 | E20: 0 | F20: 0 | G20: 0 | H20: 1965.64 | I20: 0 | J20: 0 | K20: 0 | L20: =SUM(C20:K20)
B21: пени | C21: 0 | D21: 0 | E21: 0 | F21: 0 | G21: 0 | H21: 43474.47 | I21: 0 | J21: 0 | K21: 0 | L21: =SUM(C21:K21)
A22: Направлено исполнительных документов в УФССП, ПФ РФ, Сбербанк РФ | B22: к-во/р.с | C22: 0 | D22: 0 | E22: 0 | F22: 0 | G22: 55/30 | H22: 0 | I22: 0 | J22: 0 | K22: 0 | L22: =SUM(C22:K22)
B23: долг | C23: 0 | D23: 0 | E23: 0 | F23: 0 | G23: 1326969.2 | H23: 0 | I23: 0 | J23: 0 | K23: 0 | L23: =SUM(C23:K23)
B24: пени | C24: 0 | D24: 0 | E24: 0 | F24: 0 | G24: 745987.22 | H24: 0 | I24: 0 | J24: 0 | K24: 0 | L24: =SUM(C24:K24)
B25: г/п | C25: 0 | D25: 0 | E25: 0 | F25: 0 | G25: 74782.79 | H25: 0 | I25: 0 | J25: 0 | K25: 0 | L25: =SUM(C25:K25)
A26: Оплачено г/п (по физ.лицам) | B26: сумма | C26: 0 | D26: 5497 | E26: 0 | F26: 0 | G26: 0 | H26: 155208 | I26: 58094 | J26: 0 | K26: 0 | L26: =SUM(C26:K26)
A27: Применен судом срок исковой давности | B27: к-во | C27: 0 | D27: 0 | E27: 0 | F27: 0 | G27: 0 | H27: 0 | I27: 0 | J27: 0 | K27: 0 | L27: =SUM(C27:K27)
B28: сумма | C28: 0 | D28: 0 | E28: 0 | F28: 0 | G28: 0 | H28: 0 | I28: 0 | J28: 0 | K28: 0 | L28: =SUM(C28:K28)
A29: Возвращено ден. ср. через ССП (сумма) | B29: долг | C29: 1749278.2 | D29: 0 | E29: -209206.09 | F29: 0 | G29: 775503.56 | H29: 2081281.1 | I29: 0 | J29: 532916.93 | K29: 0 | L29: =SUM(C29:K29)
B30: пени | C30: 486368.59 | D30: 0 | E30: 94804.06 | F30: 0 | G30: 195661.34 | H30: 568208.43 | I30: 0 | J30: 25869.99 | K30: 0 | L30: =SUM(C30:K30)
A31: Возвращено ден. ср. через Сбербанк и Пенсионный (сумма) | B31: долг | C31: 1740845.4 | D31: 0 | E31: 958552.37 | F31: 0 | G31: 899217.65 | H31: 1247258.3 | I31: 0 | J31: 136271.52 | K31: 0 | L31: =SUM(C31:K31)
A32: Предъявлено исковых заявлений | B32: к-во | C32: 100 | D32: 0 | E32: 50 | F32: 50 | G32: 50 | H32: 50 | I32: 0 | J32: 0 | K32: 0 | L32: =SUM(C32:K32)
B33: долг | C33: 11875474 | D33: 0 | E33: 2842935.8 | F33: 3006353.3 | G33: 1442758.9 | H33: 2503006.1 | I33: 0 | J33: 0 | K33: 0 | L33: =SUM(C33:K33)
B34: пени | C34: 12345616 | D34: 0 | E34: 1981337.8 | F34: 2751073.8 | G34: 1228729.4 | H34: 2470873.1 | I34: 0 | J34: 0 | K34: 0 | L34: =SUM(C34:K34)
B35: г/п | C35: 547353.2 | D35: 0 | E35: 167691.4 | F35: 229066 | G35: 122228.65 | H35: 226933 | I35: 0 | J35: 0 | K35: 0 | L35: =SUM(C35:K35)
A36: Удовлетворено в пользу АО "Омск РТС" исковых заявлений | B36: к-во | C36: 0 | D36: 0 | E36: 0 | F36: 0 | G36: 53 | H36: 9 | I36: 0 | J36: 1 | K36: 0 | L36: =SUM(C36:K36)
B37: долг | C37: 0 | D37: 0 | E37: 0 | F37: 0 | G37: 2750215.5 | H37: 479376.22 | I37: 0 | J37: 4134.71 | K37: 0 | L37: =SUM(C37:K37)
B38: пени | C38: 0 | D38: 0 | E38: 0 | F38: 0 | G38: 1788243.5 | H38: 130522.86 | I38: 0 | J38: 1300 | K38: 0 | L38: =SUM(C38:K38)
B39: г/п | C39: 0 | D39: 0 | E39: 0 | F39: 0 | G39: 358225.98 | H39: 37314.28 | I39: 0 | J39: 4000 | K39: 0 | L39: =SUM(C39:K39)
A40: Подготовка правового заключения о списании ДЗ | B40: к-во | C40: 0 | D40: 0 | E40: 0 | F40: 0 | G40: 2 | H40: 1 | I40: 0 | J40: 0 | K40: 0 | L40: =SUM(C40:K40)
...

Sheet мар
A1: месяц | B1: ед.изм | C1: Кравец Е.А. (САО) | D1: Лощинина М.А. (САО) | E1: Павлова Ю.В. (КАО) | F1: Кель М.В. (КАО) | G1: Епанчинцева Ю.Н. (ЦАО) | H1: Колонтаева А.Н. (ОАО) | I1: Барныч Г.М. (ОАО) | J1: Колонтаева А.Н. (ЛАО) | K1: Барныч Г.М. (ЛАО) | L1: Итого
A2: Принято участие в с/з, беседах | B2: к-во | C2: 12 | D2: 10 | E2: 22 | F2: 26 | G2: 44 | H2: 53 | I2: 15 | J2: 1 | K2: 0 | L2: =SUM(C2:K2)
A3: Предъявлено заявлений о вынесении судебного приказа | B3: к-во | C3: 0 | D3: 87 | E3: 10 | F3: 85 | G3: 0 | H3: 0 | I3: 150 | J3: 0 | K3: 50 | L3: =SUM(C3:K3)
B4: долг | C4: 0 | D4: 10140932 | E4: 497769.63 | F4: 3341023.4 | G4: 0 | H4: 0 | I4: 7259129.8 | J4: 0 | K4: 3271442.1 | L4: =SUM(C4:K4)
B5: пени | C5: 0 | D5: 5312487.6 | E5: 239346.05 | F5: 2440331.5 | G5: 0 | H5: 0 | I5: 4027618.5 | J5: 0 | K5: 2430417 | L5: =SUM(C5:K5)
B6: г/п | C6: 0 | D6: 223071 | E6: 20616 | F6: 162746 | G6: 0 | H6: 0 | I6: 350707 | J6: 0 | K6: 77514 | L6: =SUM(C6:K6)
A7: Удовлетворено в пользу АО "Омск РТС" заявлений о вынесении судебных приказов | B7: к-во | C7: 0 | D7: 0 | E7: 0 | F7: 0 | G7: 42 | H7: 110 | I7: 0 | J7: 101 | K7: 0 | L7: =SUM(C7:K7)
B8: долг | C8: 0 | D8: 0 | E8: 0 | F8: 0 | G8: 1716083.9 | H8: 4169150.1 | I8: 0 | J8: 7982772.5 | K8: 0 | L8: =SUM(C8:K8)
B9: пени | C9: 0 | D9: 0 | E9: 0 | F9: 0 | G9: 1559527.4 | H9: 2552572.5 | I9: 0 | J9: 8982470.3 | K9: 0 | L9: =SUM(C9:K9)
B10: г/п | C10: 0 | D10: 0 | E10: 0 | F10: 0 | G10: 94890.03 | H10: 190701 | I10: 0 | J10: 328178 | K10: 0 | L10: =SUM(C10:K10)
A11: Заявления нах-ся в стадии рассмотрения | B11: к-во | C11: 286 | D11: 0 | E11: 1347 | F11: 1322 | G11: 961 | H11: 121 | I11: 317 | J11: 0 | K11: 63 | L11: =SUM(C11:K11)
B12: долг | C12: 16243851 | D12: 0 | E12: 56703545 | F12: 60280408 | G12: 58880752 | H12: 5948298.4 | I12: 16678428 | J12: 0 | K12: 3965558.5 | L12: =SUM(C12:K12)
B13: пени | C13: 16846281 | D13: 0 | E13: 37037616 | F13: 36197395 | G13: 47682687 | H13: 5889708.9 | I13: 9921973 | J13: 0 | K13: 3428348.3 | L13: =SUM(C13:K13)
B14: г/п | C14: 1230000 | D14: 0 | E14: 4267722.5 | F14: 2539.5 | G14: 1424266.4 | H14: 345510 | I14: 718992 | J14: 0 | K14: 114923 | L14: =SUM(C14:K14)
A15: Получено исполнительных документов | B15: к-во | C15: 40 | D15: 103 | E15: 0 | F15: 0 | G15: 53 | H15: 32 | I15: 0 | J15: 44 | K15: 0 | L15: =SUM(C15:K15)
B16: долг | C16: 1567659 | D16: 5026230.6 | E16: 0 | F16: 0 | G16: 1716083.9 | H16: 757482.21 | I16: 0 | J16: 1628203 | K16: 0 | L16: =SUM(C16:K16)
B17: пени | C17: 845805.49 | D17: 2633819.7 | E17: 0 | F17: 0 | G17: 1559527.4 | H17: 296388.98 | I17: 0 | J17: 1356900 | K17: 0 | L17: =SUM(C17:K17)
B18: г/п | C18: 94492 | D18: 236023 | E18: 0 | F18: 0 | G18: 94890.03 | H18: 56555.6 | I18: 0 | J18: 64303.6 | K18: 0 | L18: =SUM(C18:K18)
A19: Отказ от иска в связи с оплатой долга | B19: к-во | C19: 0 | D19: 0 | E19: 0 | F19: 0 | G19: 0 | H19: 2 | I19: 0 | J19: 0 | K19: 0 | L19: =SUM(C19:K19)
B20: долг | C20: 0 | D20: 0 | E20: 0 | F20: 0 | G20: 0 | H20: 103593.17 | I20: 0 | J20: 0 | K20: 0 | L20: =SUM(C20:K20)
B21: пени | C21: 0 | D21: 0 | E21: 0 | F21: 0 | G21: 0 | H21: 51207.72 | I21: 0 | J21: 0 | K21: 0 | L21: =SUM(C21:K21)
A22: Направлено исполнительных документов в УФССП, ПФ РФ, Сбербанк РФ | B22: к-во | C22: 40/22 | D22: 103/65 | E22: 0 | F22: 0 | G22: 53/42 | H22: 32/22 | I22: 0 | J22: 44/20 | K22: 0 | L22: =SUM(C22:K22)
B23: долг | C23: 1567659 | D23: 5026230.6 | E23: 0 | F23: 0 | G23: 1716083.9 | H23: 757482.21 | I23: 0 | J23: 1628203 | K23: 0 | L23: =SUM(C23:K23)
B24: пени | C24: 845805.49 | D24: 2633819.7 | E24: 0 | F24: 0 | G24: 1559527.4 | H24: 296388.98 | I24: 0 | J24: 1356900 | K24: 0 | L24: =SUM(C24:K24)
B25: г/п | C25: 94492 | D25: 236023 | E25: 0 | F25: 0 | G25: 94890.03 | H25: 56555.6 | I25: 0 | J25: 64303.6 | K25: 0 | L25: =SUM(C25:K25)
A26: Оплачено г/п (по физ.лицам) | B26: сумма | C26: 507502 | D26: 0 | E26: 0 | F26: 0 | G26: 263083 | H26: 168402 | I26: 892254 | J26: 0 | K26: 330907 | L26: =SUM(C26:K26)
A27: Применен судом срок исковой давности | B27: к-во | C27: 18 | D27: 0 | E27: 0 | F27: 0 | G27: 0 | I27: 0 | J27: 0 | K27: 0 | L27: =SUM(C27:K27)
B28: сумма | C28: 1095348.2 | D28: 0 | E28: 0 | F28: 0 | G28: 0 | H28: 0 | I28: 0 | J28: 0 | K28: 0 | L28: =SUM(C28:K28)
A29: Возвращено ден. ср. через ССП (сумма) | B29: долг | C29: 2088426.5 | D29: 0 | E29: 180896.23 | F29: 0 | G29: 698858.24 | H29: 1619715.6 | I29: 0 | J29: 546276.37 | K29: 0 | L29: =SUM(C29:K29)
B30: пени | C30: 782551.74 | D30: 0 | E30: 253813.96 | F30: 0 | G30: 367891.66 | H30: 690538.02 | I30: 0 | J30: 81916.21 | K30: 0 | L30: =SUM(C30:K30)
A31: Возвращено ден. ср. через Сбербанк и Пенсионный (сумма) | B31: долг | C31: 2916748 | D31: 0 | E31: 1043151.5 | F31: 0 | G31: 2106729.6 | H31: 879896.1 | I31: 0 | J31: 164120.41 | K31: 0 | L31: =SUM(C31:K31)
A32: Предъявлено исковых заявлений | B32: к-во | C32: 101 | D32: 0 | E32: 50 | F32: 43 | G32: 42 | H32: 50 | I32: 0 | J32: 0 | K32: 0 | L32: =SUM(C32:K32)
B33: долг | C33: 7324869.2 | D33: 0 | E33: 1736945.6 | F33: 2132468.5 | G33: 2448393.1 | H33: 2612550.6 | I33: 0 | J33: 0 | K33: 0 | L33: =SUM(C33:K33)
B34: пени | C34: 7307112.8 | D34: 0 | E34: 982839.5 | F34: 1720317.3 | G34: 1682494.1 | H34: 1745135.1 | I34: 0 | J34: 0 | K34: 0 | L34: =SUM(C34:K34)
B35: г/п | C35: 535935 | D35: 0 | E35: 133670 | F35: 143530 | G35: 212023 | H35: 218689 | I35: 0 | J35: 0 | K35: 0 | L35: =SUM(C35:K35)
A36: Удовлетворено в пользу АО "Омск РТС" исковых заявлений | B36: к-во | C36: 0 | D36: 0 | E36: 0 | F36: 0 | G36: 32 | H36: 13 | I36: 0 | J36: 1 | K36: 0 | L36: =SUM(C36:K36)
B37: долг | C37: 0 | D37: 0 | E37: 0 | F37: 0 | G37: 1596223.4 | H37: 579603.8 | I37: 0 | J37: 68386.36 | K37: 0 | L37: =SUM(C37:K37)
B38: пени | C38: 0 | D38: 0 | E38: 0 | F38: 0 | G38: 928214.36 | H38: 404356.08 | I38: 0 | J38: 9853.6 | K38: 0 | L38: =SUM(C38:K38)
B39: г/п | C39: 0 | D39: 0 | E39: 0 | F39: 0 | G39: 226987.79 | H39: 55697 | I39: 0 | J39: 4000 | K39: 0 | L39: =SUM(C39:K39)
A40: Подготовка правового заключения о списании ДЗ | B40: к-во | C40: 0 | D40: 0 | E40: 0 | F40: 0 | G40: 12 | H40: 1 | I40: 0 | J40: 1 | K40: 0 | L40: =SUM(C40:K40)
...

Sheet I кв
A1: месяц | B1: ед.изм | C1: Кравец Е.А. (САО) | D1: Лощинина М.А. (САО) | E1: Павлова Ю.В. (КАО) | F1: Кель М.В. (КАО) | G1: Епанчинцева Ю.Н. (ЦАО) | H1: Колонтаева А.Н. (ОАО) | I1: Барныч Г.М. (ОАО) | J1: Колонтаева А.Н. (ЛАО) | K1: Барныч Г.М. (ЛАО) | L1: Итого
A2: Принято участие в с/з, беседах | B2: к-во | C2: =янв!C2+фев!C2+мар!C2 | D2: =янв!D2+фев!D2+мар!D2 | E2: =янв!E2+фев!E2+мар!E2 | F2: =янв!F2+фев!F2+мар!F2 | G2: =янв!G2+фев!G2+мар!G2 | H2: =янв!H2+фев!H2+мар!H2 | I2: =янв!I2+фев!I2+мар!I2 | J2: =янв!J2+фев!J2+мар!J2 | ... L2: =янв!L2+фев!L2+мар!L2
A3: Предъявлено заявлений о вынесении судебного приказа | B3: к-во | C3: =янв!C3+фев!C3+мар!C3 | D3: =янв!D3+фев!D3+мар!D3 | E3: =янв!E3+фев!E3+мар!E3 | F3: =янв!F3+фев!F3+мар!F3 | G3: =янв!G3+фев!G3+мар!G3 | H3: =янв!H3+фев!H3+мар!H3 | I3: =янв!I3+фев!I3+мар!I3 | J3: =янв!J3+фев!J3+мар!J3 | ... L3: =янв!L3+фев!L3+мар!L3
B4: долг | C4: =янв!C4+фев!C4+мар!C4 | D4: =янв!D4+фев!D4+мар!D4 | E4: =янв!E4+фев!E4+мар!E4 | F4: =янв!F4+фев!F4+мар!F4 | G4: =янв!G4+фев!G4+мар!G4 | H4: =янв!H4+фев!H4+мар!H4 | I4: =янв!I4+фев!I4+мар!I4 | J4: =янв!J4+фев!J4+мар!J4 | ... L4: =янв!L4+фев!L4+мар!L4
B5: пени | C5: =янв!C5+фев!C5+мар!C5 | D5: =янв!D5+фев!D5+мар!D5 | E5: =янв!E5+фев!E5+мар!E5 | F5: =янв!F5+фев!F5+мар!F5 | G5: =янв!G5+фев!G5+мар!G5 | H5: =янв!H5+фев!H5+мар!H5 | I5: =янв!I5+фев!I5+мар!I5 | J5: =янв!J5+фев!J5+мар!J5 | ... L5: =янв!L5+фев!L5+мар!L5
B6: г/п | C6: =янв!C6+фев!C6+мар!C6 | D6: =янв!D6+фев!D6+мар!D6 | E6: =янв!E6+фев!E6+мар!E6 | F6: =янв!F6+фев!F6+мар!F6 | G6: =янв!G6+фев!G6+мар!G6 | H6: =янв!H6+фев!H6+мар!H6 | I6: =янв!I6+фев!I6+мар!I6 | J6: =янв!J6+фев!J6+мар!J6 | ... L6: =янв!L6+фев!L6+мар!L6
A7: Удовлетворено в пользу АО "Омск РТС" заявлений о вынесении судебных приказов | B7: к-во | C7: =янв!C7+фев!C7+мар!C7 | D7: =янв!D7+фев!D7+мар!D7 | E7: =янв!E7+фев!E7+мар!E7 | F7: =янв!F7+фев!F7+мар!F7 | G7: =янв!G7+фев!G7+мар!G7 | H7: =янв!H7+фев!H7+мар!H7 | I7: =янв!I7+фев!I7+мар!I7 | J7: =янв!J7+фев!J7+мар!J7 | ... L7: =янв!L7+фев!L7+мар!L7
B8: долг | C8: =янв!C8+фев!C8+мар!C8 | D8: =янв!D8+фев!D8+мар!D8 | E8: =янв!E8+фев!E8+мар!E8 | F8: =янв!F8+фев!F8+мар!F8 | G8: =янв!G8+фев!G8+мар!G8 | H8: =янв!H8+фев!H8+мар!H8 | I8: =янв!I8+фев!I8+мар!I8 | J8: =янв!J8+фев!J8+мар!J8 | ... L8: =янв!L8+фев!L8+мар!L8
B9: пени | C9: =янв!C9+фев!C9+мар!C9 | D9: =янв!D9+фев!D9+мар!D9 | E9: =янв!E9+фев!E9+мар!E9 | F9: =янв!F9+фев!F9+мар!F9 | G9: =янв!G9+фев!G9+мар!G9 | H9: =янв!H9+фев!H9+мар!H9 | I9: =янв!I9+фев!I9+мар!I9 | J9: =янв!J9+фев!J9+мар!J9 | ... L9: =янв!L9+фев!L9+мар!L9
B10: г/п | C10: =янв!C10+фев!C10+мар!C10 | D10: =янв!D10+фев!D10+мар!D10 | E10: =янв!E10+фев!E10+мар!E10 | F10: =янв!F10+фев!F10+мар!F10 | G10: =янв!G10+фев!G10+мар!G10 | H10: =янв!H10+фев!H10+мар!H10 | I10: =янв!I10+фев!I10+мар!I10 | J10: =янв!J10+фев!J10+мар!J10 | ... L10: =янв!L10+фев!L10+мар!L10
A11: Заявления нах-ся в стадии рассмотрения | B11: к-во | C11: =янв!C11+фев!C11+мар!C11 | D11: =янв!D11+фев!D11+мар!D11 | E11: =янв!E11+фев!E11+мар!E11 | F11: =янв!F11+фев!F11+мар!F11 | G11: =янв!G11+фев!G11+мар!G11 | H11: =янв!H11+фев!H11+мар!H11 | I11: =янв!I11+фев!I11+мар!I11 | J11: =янв!J11+фев!J11+мар!J11 | ... L11: =янв!L11+фев!L11+мар!L11
B12: долг | C12: =янв!C12+фев!C12+мар!C12 | D12: =янв!D12+фев!D12+мар!D12 | E12: =янв!E12+фев!E12+мар!E12 | F12: =янв!F12+фев!F12+мар!F12 | G12: =янв!G12+фев!G12+мар!G12 | H12: =янв!H12+фев!H12+мар!H12 | I12: =янв!I12+фев!I12+мар!I12 | J12: =янв!J12+фев!J12+мар!J12 | ... L12: =янв!L12+фев!L12+мар!L12
B13: пени | C13: =янв!C13+фев!C13+мар!C13 | D13: =янв!D13+фев!D13+мар!D13 | E13: =янв!E13+фев!E13+мар!E13 | F13: =янв!F13+фев!F13+мар!F13 | G13: =янв!G13+фев!G13+мар!G13 | H13: =янв!H13+фев!H13+мар!H13 | I13: =янв!I13+фев!I13+мар!I13 | J13: =янв!J13+фев!J13+мар!J13 | ... L13: =янв!L13+фев!L13+мар!L13
B14: г/п | C14: =янв!C14+фев!C14+мар!C14 | D14: =янв!D14+фев!D14+мар!D14 | E14: =янв!E14+фев!E14+мар!E14 | F14: =янв!F14+фев!F14+мар!F14 | G14: =янв!G14+фев!G14+мар!G14 | H14: =янв!H14+фев!H14+мар!H14 | I14: =янв!I14+фев!I14+мар!I14 | J14: =янв!J14+фев!J14+мар!J14 | ... L14: =янв!L14+фев!L14+мар!L14
A15: Получено исполнительных документов | B15: к-во | C15: =янв!C15+фев!C15+мар!C15 | D15: =янв!D15+фев!D15+мар!D15 | E15: =янв!E15+фев!E15+мар!E15 | F15: =янв!F15+фев!F15+мар!F15 | G15: =янв!G15+фев!G15+мар!G15 | H15: =янв!H15+фев!H15+мар!H15 | I15: =янв!I15+фев!I15+мар!I15 | J15: =янв!J15+фев!J15+мар!J15 | ... L15: =янв!L15+фев!L15+мар!L15
B16: долг | C16: =янв!C16+фев!C16+мар!C16 | D16: =янв!D16+фев!D16+мар!D16 | E16: =янв!E16+фев!E16+мар!E16 | F16: =янв!F16+фев!F16+мар!F16 | G16: =янв!G16+фев!G16+мар!G16 | H16: =янв!H16+фев!H16+мар!H16 | I16: =янв!I16+фев!I16+мар!I16 | J16: =янв!J16+фев!J16+мар!J16 | ... L16: =янв!L16+фев!L16+мар!L16
B17: пени | C17: =янв!C17+фев!C17+мар!C17 | D17: =янв!D17+фев!D17+мар!D17 | E17: =янв!E17+фев!E17+мар!E17 | F17: =янв!F17+фев!F17+мар!F17 | G17: =янв!G17+фев!G17+мар!G17 | H17: =янв!H17+фев!H17+мар!H17 | I17: =янв!I17+фев!I17+мар!I17 | J17: =янв!J17+фев!J17+мар!J17 | ... L17: =янв!L17+фев!L17+мар!L17
B18: г/п | C18: =янв!C18+фев!C18+мар!C18 | D18: =янв!D18+фев!D18+мар!D18 | E18: =янв!E18+фев!E18+мар!E18 | F18: =янв!F18+фев!F18+мар!F18 | G18: =янв!G18+фев!G18+мар!G18 | H18: =янв!H18+фев!H18+мар!H18 | I18: =янв!I18+фев!I18+мар!I18 | J18: =янв!J18+фев!J18+мар!J18 | ... L18: =янв!L18+фев!L18+мар!L18
A19: Отказ от иска в связи с оплатой долга | B19: к-во | C19: =янв!C19+фев!C19+мар!C19 | D19: =янв!D19+фев!D19+мар!D19 | E19: =янв!E19+фев!E19+мар!E19 | F19: =янв!F19+фев!F19+мар!F19 | G19: =янв!G19+фев!G19+мар!G19 | H19: =янв!H19+фев!H19+мар!H19 | I19: =янв!I19+фев!I19+мар!I19 | J19: =янв!J19+фев!J19+мар!J19 | ... L19: =янв!L19+фев!L19+мар!L19
B20: долг | C20: =янв!C20+фев!C20+мар!C20 | D20: =янв!D20+фев!D20+мар!D20 | E20: =янв!E20+фев!E20+мар!E20 | F20: =янв!F20+фев!F20+мар!F20 | G20: =янв!G20+фев!G20+мар!G20 | H20: =янв!H20+фев!H20+мар!H20 | I20: =янв!I20+фев!I20+мар!I20 | J20: =янв!J20+фев!J20+мар!J20 | ... L20: =янв!L20+фев!L20+мар!L20
B21: пени | C21: =янв!C21+фев!C21+мар!C21 | D21: =янв!D21+фев!D21+мар!D21 | E21: =янв!E21+фев!E21+мар!E21 | F21: =янв!F21+фев!F21+мар!F21 | G21: =янв!G21+фев!G21+мар!G21 | H21: =янв!H21+фев!H21+мар!H21 | I21: =янв!I21+фев!I21+мар!I21 | J21: =янв!J21+фев!J21+мар!J21 | ... L21: =янв!L21+фев!L21+мар!L21
A22: Направлено исполнительных документов в УФССП, ПФ РФ, Сбербанк РФ | B22: к-во/р.с | C22: 40/22 | D22: 103/65 | E22: 0 | F22: 0 | G22: 108/72 | H22: 120/77 | I22: 0 | J22: 44/20 | K22: 0 | L22: 415/256
B23: долг | C23: =янв!C23+фев!C23+мар!C23 | D23: =янв!D23+фев!D23+мар!D23 | E23: =янв!E23+фев!E23+мар!E23 | F23: =янв!F23+фев!F23+мар!F23 | G23: =янв!G23+фев!G23+мар!G23 | H23: =янв!H23+фев!H23+мар!H23 | I23: =янв!I23+фев!I23+мар!I23 | J23: =янв!J23+фев!J23+мар!J23 | ... L23: =янв!L23+фев!L23+мар!L23
B24: пени | C24: =янв!C24+фев!C24+мар!C24 | D24: =янв!D24+фев!D24+мар!D24 | E24: =янв!E24+фев!E24+мар!E24 | F24: =янв!F24+фев!F24+мар!F24 | G24: =янв!G24+фев!G24+мар!G24 | H24: =янв!H24+фев!H24+мар!H24 | I24: =янв!I24+фев!I24+мар!I24 | J24: =янв!J24+фев!J24+мар!J24 | ... L24: =янв!L24+фев!L24+мар!L24
B25: г/п | C25: =янв!C25+фев!C25+мар!C25 | D25: =янв!D25+фев!D25+мар!D25 | E25: =янв!E25+фев!E25+мар!E25 | F25: =янв!F25+фев!F25+мар!F25 | G25: =янв!G25+фев!G25+мар!G25 | H25: =янв!H25+фев!H25+мар!H25 | I25: =янв!I25+фев!I25+мар!I25 | J25: =янв!J25+фев!J25+мар!J25 | ... L25: =янв!L25+фев!L25+мар!L25
A26: Оплачено г/п (по физ.лицам) | B26: сумма | C26: =янв!C26+фев!C26+мар!C26 | D26: =янв!D26+фев!D26+мар!D26 | E26: =янв!E26+фев!E26+мар!E26 | F26: =янв!F26+фев!F26+мар!F26 | G26: =янв!G26+фев!G26+мар!G26 | H26: =янв!H26+фев!H26+мар!H26 | I26: =янв!I26+фев!I26+мар!I26 | J26: =янв!J26+фев!J26+мар!J26 | ... L26: =янв!L26+фев!L26+мар!L26
A27: Применен судом срок исковой давности | B27: к-во | C27: =янв!C27+фев!C27+мар!C27 | D27: =янв!D27+фев!D27+мар!D27 | E27: =янв!E27+фев!E27+мар!E27 | F27: =янв!F27+фев!F27+мар!F27 | G27: =янв!G27+фев!G27+мар!G27 | H27: =янв!H27+фев!H27+мар!H27 | I27: =янв!I27+фев!I27+мар!I27 | J27: =янв!J27+фев!J27+мар!J27 | ... L27: =янв!L27+фев!L27+мар!L27
B28: сумма | C28: =янв!C28+фев!C28+мар!C28 | D28: =янв!D28+фев!D28+мар!D28 | E28: =янв!E28+фев!E28+мар!E28 | F28: =янв!F28+фев!F28+мар!F28 | G28: =янв!G28+фев!G28+мар!G28 | H28: =янв!H28+фев!H28+мар!H28 | I28: =янв!I28+фев!I28+мар!I28 | J28: =янв!J28+фев!J28+мар!J28 | ... L28: =янв!L28+фев!L28+мар!L28
A29: Возвращено ден. ср. через ССП (сумма) | B29: долг | C29: =янв!C29+фев!C29+мар!C29 | D29: =янв!D29+фев!D29+мар!D29 | E29: =янв!E29+фев!E29+мар!E29 | F29: =янв!F29+фев!F29+мар!F29 | G29: =янв!G29+фев!G29+мар!G29 | H29: =янв!H29+фев!H29+мар!H29 | I29: =янв!I29+фев!I29+мар!I29 | J29: =янв!J29+фев!J29+мар!J29 | ... L29: =янв!L29+фев!L29+мар!L29
B30: пени | C30: =янв!C30+фев!C30+мар!C30 | D30: =янв!D30+фев!D30+мар!D30 | E30: =янв!E30+фев!E30+мар!E30 | F30: =янв!F30+фев!F30+мар!F30 | G30: =янв!G30+фев!G30+мар!G30 | H30: =янв!H30+фев!H30+мар!H30 | I30: =янв!I30+фев!I30+мар!I30 | J30: =янв!J30+фев!J30+мар!J30 | ... L30: =янв!L30+фев!L30+мар!L30
A31: Возвращено ден. ср. через СБ и Пенсионный (сумма) | B31: долг | C31: =янв!C31+фев!C31+мар!C31 | D31: =янв!D31+фев!D31+мар!D31 | E31: =янв!E31+фев!E31+мар!E31 | F31: =янв!F31+фев!F31+мар!F31 | G31: =янв!G31+фев!G31+мар!G31 | H31: =янв!H31+фев!H31+мар!H31 | I31: =янв!I31+фев!I31+мар!I31 | J31: =янв!J31+фев!J31+мар!J31 | ... L31: =янв!L31+фев!L31+мар!L31
A32: Предъявлено исковых заявлений | B32: к-во | C32: =янв!C32+фев!C32+мар!C32 | D32: =янв!D32+фев!D32+мар!D32 | E32: =янв!E32+фев!E32+мар!E32 | F32: =янв!F32+фев!F32+мар!F32 | G32: =янв!G32+фев!G32+мар!G32 | H32: =янв!H32+фев!H32+мар!H32 | I32: =янв!I32+фев!I32+мар!I32 | J32: =янв!J32+фев!J32+мар!J32 | ... L32: =янв!L32+фев!L32+мар!L32
B33: долг | C33: =янв!C33+фев!C33+мар!C33 | D33: =янв!D33+фев!D33+мар!D33 | E33: =янв!E33+фев!E33+мар!E33 | F33: =янв!F33+фев!F33+мар!F33 | G33: =янв!G33+фев!G33+мар!G33 | H33: =янв!H33+фев!H33+мар!H33 | I33: =янв!I33+фев!I33+мар!I33 | J33: =янв!J33+фев!J33+мар!J33 | ... L33: =янв!L33+фев!L33+мар!L33
B34: пени | C34: =янв!C34+фев!C34+мар!C34 | D34: =янв!D34+фев!D34+мар!D34 | E34: =янв!E34+фев!E34+мар!E34 | F34: =янв!F34+фев!F34+мар!F34 | G34: =янв!G34+фев!G34+мар!G34 | H34: =янв!H34+фев!H34+мар!H34 | I34: =янв!I34+фев!I34+мар!I34 | J34: =янв!J34+фев!J34+мар!J34 | ... L34: =янв!L34+фев!L34+мар!L34
B35: г/п | C35: =янв!C35+фев!C35+мар!C35 | D35: =янв!D35+фев!D35+мар!D35 | E35: =янв!E35+фев!E35+мар!E35 | F35: =янв!F35+фев!F35+мар!F35 | G35: =янв!G35+фев!G35+мар!G35 | H35: =янв!H35+фев!H35+мар!H35 | I35: =янв!I35+фев!I35+мар!I35 | J35: =янв!J35+фев!J35+мар!J35 | ... L35: =янв!L35+фев!L35+мар!L35
A36: Удовлетворено в пользу АО "Омск РТС" исковых заявлений | B36: к-во | C36: =янв!C36+фев!C36+мар!C36 | D36: =янв!D36+фев!D36+мар!D36 | E36: =янв!E36+фев!E36+мар!E36 | F36: =янв!F36+фев!F36+мар!F36 | G36: =янв!G36+фев!G36+мар!G36 | H36: =янв!H36+фев!H36+мар!H36 | I36: =янв!I36+фев!I36+мар!I36 | J36: =янв!J36+фев!J36+мар!J36 | ... L36: =янв!L36+фев!L36+мар!L36
B37: долг | C37: =янв!C37+фев!C37+мар!C37 | D37: =янв!D37+фев!D37+мар!D37 | E37: =янв!E37+фев!E37+мар!E37 | F37: =янв!F37+фев!F37+мар!F37 | G37: =янв!G37+фев!G37+мар!G37 | H37: =янв!H37+фев!H37+мар!H37 | I37: =янв!I37+фев!I37+мар!I37 | J37: =янв!J37+фев!J37+мар!J37 | ... L37: =янв!L37+фев!L37+мар!L37
B38: пени | C38: =янв!C38+фев!C38+мар!C38 | D38: =янв!D38+фев!D38+мар!D38 | E38: =янв!E38+фев!E38+мар!E38 | F38: =янв!F38+фев!F38+мар!F38 | G38: =янв!G38+фев!G38+мар!G38 | H38: =янв!H38+фев!H38+мар!H38 | I38: =янв!I38+фев!I38+мар!I38 | J38: =янв!J38+фев!J38+мар!J38 | ... L38: =янв!L38+фев!L38+мар!L38
B39: г/п | C39: =янв!C39+фев!C39+мар!C39 | D39: =янв!D39+фев!D39+мар!D39 | E39: =янв!E39+фев!E39+мар!E39 | F39: =янв!F39+фев!F39+мар!F39 | G39: =янв!G39+фев!G39+мар!G39 | H39: =янв!H39+фев!H39+мар!H39 | I39: =янв!I39+фев!I39+мар!I39 | J39: =янв!J39+фев!J39+мар!J39 | ... L39: =янв!L39+фев!L39+мар!L39
A40: Подготовка правового заключения о списании ДЗ | B40: к-во | C40: =янв!C40+фев!C40+мар!C40 | D40: =янв!D40+фев!D40+мар!D40 | E40: =янв!E40+фев!E40+мар!E40 | F40: =янв!F40+фев!F40+мар!F40 | G40: =янв!G40+фев!G40+мар!G40 | H40: =янв!H40+фев!H40+мар!H40 | I40: =янв!I40+фев!I40+мар!I40 | J40: =янв!J40+фев!J40+мар!J40 | ... L40: =янв!L40+фев!L40+мар!L40
...
